Workbook

Sheet LEIA-ME
A1: ANÁLISE DE FOLHA DE PONTO: HORAS EXTRAS, DESCONTOS E COMPENSAÇÃO
A3: PARA QUE SERVE
A4: Transcreva o ponto batido pelo funcionário e a planilha calcula: o horário a cumprir, as horas extras reais, os descontos prováveis e como distribuir as horas extras que passam do limite diário (por padrão 2h/dia). No fim, monta a folha de ponto ajustada, com a explicação de cada linha.
A5: COMO USAR (5 PASSOS)
A6: 1) Aba "Parametros": digite os dados do cabeçalho da folha de ponto, o 1º dia do mês, o limite de hora extra por dia, o horário padrão e os feriados.
A7: 2) Aba "1_Ponto_Batido": copie, dia a dia, os horários escritos na folha de papel (entrada, parada, retorno, saída, extras). Anote rasuras na coluna de observações.
A8: 3) Aba "2_Analise": preencha SÓ as exceções nas 3 colunas amarelas: situação (folga no meio da semana, falta, dia ainda não ocorrido = PREVISTO), liberação antecipada (hora em que a diretoria liberou o setor) e saída real informada (quando a pessoa ficou além do que está no papel).
A9: 4) Ainda na aba 2, olhe a coluna ALERTA e o quadro RESUMO E CONFERÊNCIA (embaixo). As duas conferências devem mostrar OK.
A10: 5) Aba "3_Ponto_Ajustado": é a folha pronta para imprimir, com a explicação de cada dia. Para outro funcionário ou outro mês, salve uma cópia do arquivo, altere os Parâmetros e redigite a aba 1 e as exceções da aba 2.
A11: REGRAS USADAS NO CÁLCULO
A12: • Horas exigidas = (saída prevista − entrada prevista) − intervalo. Normalmente 8h (08:00–12:00 e 13:00–17:00). Em dia de liberação antecipada, a saída prevista passa a ser a hora da liberação (ex.: 05/10 às 14:22 = 5h22 exigidas).
A13: • Horas trabalhadas = (saída real − entrada real) − intervalo. Hora extra real = trabalhadas − exigidas. Desconto provável = exigidas − trabalhadas (ou o dia inteiro, se FALTA).
... A22: A folha ajustada é um documento de conferência e de fechamento da folha de pagamento: as linhas de COMPENSAÇÃO são horas feitas em OUTRAS datas, lançadas ali para respeitar o limite diário. Guarde sempre a folha original (aba 1). A regra de compensação (pagamento, folga, banco de horas) segue a política da organização, o contrato e a convenção coletiva: confirme com o RH/jurídico (CLT art. 59: limite de 2h extras por dia; art. 74: registro de ponto).

Sheet Parametros
A1: PARÂMETROS E DADOS DO CABEÇALHO DA FOLHA DE PONTO
A2: Células amarelas com letra azul = você informa. Todo o resto é calculado.
A3: DADOS DO CABEÇALHO (copie da folha de ponto)
A4: EMPREGADOR (nome / empresa)
A5: CEI / CNPJ nº
A6: ENDEREÇO
A7: EMPREGADO(A)
A8: FUNÇÃO
A9: CTPS nº e série
A10: DATA DE ADMISSÃO
A11: HORÁRIO DE TRABALHO SEG. A SEXTA-FEIRA
A12: HORÁRIO AOS SÁBADOS
A13: DESCANSO SEMANAL
A14: MÊS DE REFERÊNCIA (digite o 1º dia do mês) | B14: 46327
A15: MÊS (automático) | B15: =IF(B14="","",CHOOSE(MONTH(B14),"JANEIRO","FEVEREIRO","MARÇO","ABRIL","MAIO","JUNHO","JULHO","AGOSTO","SETEMBRO","OUTUBRO","NOVEMBRO","DEZEMBRO")) -> NOVEMBRO
A16: ANO (automático) | B16: =IF(B14="","",YEAR(B14)) -> 2026
A18: REGRAS DE CÁLCULO
A19: LIMITE DE HORAS EXTRAS POR DIA | B19: 0.083333333 | C19: Máximo de hora extra que pode aparecer em um mesmo dia na folha ajustada.
A20: EM DIA DE LIBERAÇÃO ANTECIPADA, LANÇAR EXTRA NO PRÓPRIO DIA? | B20: NÃO | C20: NÃO = a folha ajustada mostra a saída da liberação e todo o extra vai para compensação em outros dias (como no exemplo).
A22: HORÁRIO A CUMPRIR (padrão de cada dia da semana)
A23: Vale para qualquer dia que tenha ponto batido ou seja dia de trabalho previsto. Deixe em branco o dia sem expediente. No exemplo, sábado e domingo trabalhados foram tratados como expediente normal de 8h.
A24: DIA DA SEMANA | B24: ENTRADA | C24: PARADA (almoço) | D24: RETORNO | E24: SAÍDA | F24: HORAS EXIGIDAS
A25: Segunda-feira | B25: 0.33333333 | C25: 0.5 | D25: 0.54166667 | E25: 0.70833333 | F25: =IF(OR(B25="",E25=""),0,ROUND(IF(E25<=C25,E25-B25,(E25-B25)-(D25-C25))*1440,0)/1440) -> 0.33333333
A26: Terça-feira | B26: 0.33333333 | C26: 0.5 | D26: 0.54166667 | E26: 0.70833333 | F26: =IF(OR(B26="",E26=""),0,ROUND(IF(E26<=C26,E26-B26,(E26-B26)-(D26-C26))*1440,0)/1440) -> 0.33333333
A27: Quarta-feira | B27: 0.33333333 | C27: 0.5 | D27: 0.54166667 | E27: 0.70833333 | F27: =IF(OR(B27="",E27=""),0,ROUND(IF(E27<=C27,E27-B27,(E27-B27)-(D27-C27))*1440,0)/1440) -> 0.33333333
A28: Quinta-feira | B28: 0.33333333 | C28: 0.5 | D28: 0.54166667 | E28: 0.70833333 | F28: =IF(OR(B28="",E28=""),0,ROUND(IF(E28<=C28,E28-B28,(E28-B28)-(D28-C28))*1440,0)/1440) -> 0.33333333
A29: Sexta-feira | B29: 0.33333333 | C29: 0.5 | D29: 0.54166667 | E29: 0.70833333 | F29: =IF(OR(B29="",E29=""),0,ROUND(IF(E29<=C29,E29-B29,(E29-B29)-(D29-C29))*1440,0)/1440) -> 0.33333333
A30: Sábado | B30: 0.33333333 | C30: 0.5 | D30: 0.54166667 | E30: 0.70833333 | F30: =IF(OR(B30="",E30=""),0,ROUND(IF(E30<=C30,E30-B30,(E30-B30)-(D30-C30))*1440,0)/1440) -> 0.33333333
A31: Domingo | B31: 0.33333333 | C31: 0.5 | D31: 0.54166667 | E31: 0.70833333 | F31: =IF(OR(B31="",E31=""),0,ROUND(IF(E31<=C31,E31-B31,(E31-B31)-(D31-C31))*1440,0)/1440) -> 0.33333333
A33: FERIADOS (inclua também os estaduais, municipais e pontos facultativos da sua organização)
A34: DATA | B34: NOME DO FERIADO
A35: 46023 | B35: Confraternização Universal
A36: 46115 | B36: Sexta-feira Santa
A37: 46133 | B37: Tiradentes
A38: 46143 | B38: Dia do Trabalho
A39: 46272 | B39: Independência do Brasil
A40: 46307 | B40: Nossa Senhora Aparecida
A41: 46328 | B41: Finados
A42: 46341 | B42: Proclamação da República
A43: 46346 | B43: Consciência Negra
...

Sheet 1_Ponto_Batido
A1: 1 – PONTO BATIDO PELO FUNCIONÁRIO (transcrição da folha de ponto física)
A2: Digite nas células amarelas exatamente o que está escrito na folha de papel (horas no formato 8:00). Informe rasuras e dúvidas na coluna de observações.
A3: =" EMPREGADOR: "&Parametros!B4 -> EMPREGADOR: | I3: ="CEI / CNPJ Nº: "&Parametros!B5 -> CEI / CNPJ Nº:
A4: =" ENDEREÇO: "&Parametros!B6 -> ENDEREÇO: | I4: ="DATA DE ADMISSÃO: "&IF(Parametros!B10="","",TEXT(Parametros!B10,"dd/mm/yyyy")) -> DATA DE ADMISSÃO:
A5: =" EMPREGADO(A): "&Parametros!B7 -> EMPREGADO(A): | I5: ="CTPS Nº E SÉRIE: "&Parametros!B9 -> CTPS Nº E SÉRIE:
A6: =" FUNÇÃO: "&Parametros!B8 -> FUNÇÃO: | I6: ="HORÁRIO SEG. A SEXTA: "&Parametros!B11 -> HORÁRIO SEG. A SEXTA:
A7: =" HORÁRIO AOS SÁBADOS: "&Parametros!B12 -> HORÁRIO AOS SÁBADOS: | E7: ="DESCANSO SEMANAL: "&Parametros!B13 -> DESCANSO SEMANAL: | I7: ="MÊS: "&Parametros!B15&" ANO: "&Parametros!B16 -> MÊS: NOVEMBRO ANO: 2026
A9: DIA | B9: DIA DA SEMANA | C9: ENTRADA | D9: INTERVALO | F9: SAÍDA | G9: EXTRAS | I9: VISTO DO RESP. HORA EXTRA | J9: ASSINATURA DO FUNCIONÁRIO | K9: OBSERVAÇÕES (rasuras, dúvidas, origem do dado)
D10: PARADA | E10: RETORNO | G10: ENTRADA | H10: SAÍDA
A11: =IF(Parametros!$B$14+0<=EOMONTH(Parametros!$B$14,0),Parametros!$B$14+0,"") -> 46327 | B11: =IF(A11="","",CHOOSE(WEEKDAY(A11,2),"Segunda-feira","Terça-feira","Quarta-feira","Quinta-feira","Sexta-feira","Sábado","Domingo")) -> Domingo
A12: =IF(Parametros!$B$14+1<=EOMONTH(Parametros!$B$14,0),Parametros!$B$14+1,"") -> 46328 | B12: =IF(A12="","",CHOOSE(WEEKDAY(A12,2),"Segunda-feira","Terça-feira","Quarta-feira","Quinta-feira","Sexta-feira","Sábado","Domingo")) -> Segunda-feira
A13: =IF(Parametros!$B$14+2<=EOMONTH(Parametros!$B$14,0),Parametros!$B$14+2,"") -> 46329 | B13: =IF(A13="","",CHOOSE(WEEKDAY(A13,2),"Segunda-feira","Terça-feira","Quarta-feira","Quinta-feira","Sexta-feira","Sábado","Domingo")) -> Terça-feira
A14: =IF(Parametros!$B$14+3<=EOMONTH(Parametros!$B$14,0),Parametros!$B$14+3,"") -> 46330 | B14: =IF(A14="","",CHOOSE(WEEKDAY(A14,2),"Segunda-feira","Terça-feira","Quarta-feira","Quinta-feira","Sexta-feira","Sábado","Domingo")) -> Quarta-feira
A15: =IF(Parametros!$B$14+4<=EOMONTH(Parametros!$B$14,0),Parametros!$B$14+4,"") -> 46331 | B15: =IF(A15="","",CHOOSE(WEEKDAY(A15,2),"Segunda-feira","Terça-feira","Quarta-feira","Quinta-feira","Sexta-feira","Sábado","Domingo")) -> Quinta-feira
A16: =IF(Parametros!$B$14+5<=EOMONTH(Parametros!$B$14,0),Parametros!$B$14+5,"") -> 46332 | B16: =IF(A16="","",CHOOSE(WEEKDAY(A16,2),"Segunda-feira","Terça-feira","Quarta-feira","Quinta-feira","Sexta-feira","Sábado","Domingo")) -> Sexta-feira
A17: =IF(Parametros!$B$14+6<=EOMONTH(Parametros!$B$14,0),Parametros!$B$14+6,"") -> 46333 | B17: =IF(A17="","",CHOOSE(WEEKDAY(A17,2),"Segunda-feira","Terça-feira","Quarta-feira","Quinta-feira","Sexta-feira","Sábado","Domingo")) -> Sábado
A18: =IF(Parametros!$B$14+7<=EOMONTH(Parametros!$B$14,0),Parametros!$B$14+7,"") -> 46334 | B18: =IF(A18="","",CHOOSE(WEEKDAY(A18,2),"Segunda-feira","Terça-feira","Quarta-feira","Quinta-feira","Sexta-feira","Sábado","Domingo")) -> Domingo
A19: =IF(Parametros!$B$14+8<=EOMONTH(Parametros!$B$14,0),Parametros!$B$14+8,"") -> 46335 | B19: =IF(A19="","",CHOOSE(WEEKDAY(A19,2),"Segunda-feira","Terça-feira","Quarta-feira","Quinta-feira","Sexta-feira","Sábado","Domingo")) -> Segunda-feira
A20: =IF(Parametros!$B$14+9<=EOMONTH(Parametros!$B$14,0),Parametros!$B$14+9,"") -> 46336 | B20: =IF(A20="","",CHOOSE(WEEKDAY(A20,2),"Segunda-feira","Terça-feira","Quarta-feira","Quinta-feira","Sexta-feira","Sábado","Domingo")) -> Terça-feira
A21: =IF(Parametros!$B$14+10<=EOMONTH(Parametros!$B$14,0),Parametros!$B$14+10,"") -> 46337 | B21: =IF(A21="","",CHOOSE(WEEKDAY(A21,2),"Segunda-feira","Terça-feira","Quarta-feira","Quinta-feira","Sexta-feira","Sábado","Domingo")) -> Quarta-feira
A22: =IF(Parametros!$B$14+11<=EOMONTH(Parametros!$B$14,0),Parametros!$B$14+11,"") -> 46338 | B22: =IF(A22="","",CHOOSE(WEEKDAY(A22,2),"Segunda-feira","Terça-feira","Quarta-feira","Quinta-feira","Sexta-feira","Sábado","Domingo")) -> Quinta-feira
A23: =IF(Parametros!$B$14+12<=EOMONTH(Parametros!$B$14,0),Parametros!$B$14+12,"") -> 46339 | B23: =IF(A23="","",CHOOSE(WEEKDAY(A23,2),"Segunda-feira","Terça-feira","Quarta-feira","Quinta-feira","Sexta-feira","Sábado","Domingo")) -> Sexta-feira
A24: =IF(Parametros!$B$14+13<=EOMONTH(Parametros!$B$14,0),Parametros!$B$14+13,"") -> 46340 | B24: =IF(A24="","",CHOOSE(WEEKDAY(A24,2),"Segunda-feira","Terça-feira","Quarta-feira","Quinta-feira","Sexta-feira","Sábado","Domingo")) -> Sábado
A25: =IF(Parametros!$B$14+14<=EOMONTH(Parametros!$B$14,0),Parametros!$B$14+14,"") -> 46341 | B25: =IF(A25="","",CHOOSE(WEEKDAY(A25,2),"Segunda-feira","Terça-feira","Quarta-feira","Quinta-feira","Sexta-feira","Sábado","Domingo")) -> Domingo
A26: =IF(Parametros!$B$14+15<=EOMONTH(Parametros!$B$14,0),Parametros!$B$14+15,"") -> 46342 | B26: =IF(A26="","",CHOOSE(WEEKDAY(A26,2),"Segunda-feira","Terça-feira","Quarta-feira","Quinta-feira","Sexta-feira","Sábado","Domingo")) -> Segunda-feira
A27: =IF(Parametros!$B$14+16<=EOMONTH(Parametros!$B$14,0),Parametros!$B$14+16,"") -> 46343 | B27: =IF(A27="","",CHOOSE(WEEKDAY(A27,2),"Segunda-feira","Terça-feira","Quarta-feira","Quinta-feira","Sexta-feira","Sábado","Domingo")) -> Terça-feira
A28: =IF(Parametros!$B$14+17<=EOMONTH(Parametros!$B$14,0),Parametros!$B$14+17,"") -> 46344 | B28: =IF(A28="","",CHOOSE(WEEKDAY(A28,2),"Segunda-feira","Terça-feira","Quarta-feira","Quinta-feira","Sexta-feira","Sábado","Domingo")) -> Quarta-feira
A29: =IF(Parametros!$B$14+18<=EOMONTH(Parametros!$B$14,0),Parametros!$B$14+18,"") -> 46345 | B29: =IF(A29="","",CHOOSE(WEEKDAY(A29,2),"Segunda-feira","Terça-feira","Quarta-feira","Quinta-feira","Sexta-feira","Sábado","Domingo")) -> Quinta-feira
A30: =IF(Parametros!$B$14+19<=EOMONTH(Parametros!$B$14,0),Parametros!$B$14+19,"") -> 46346 | B30: =IF(A30="","",CHOOSE(WEEKDAY(A30,2),"Segunda-feira","Terça-feira","Quarta-feira","Quinta-feira","Sexta-feira","Sábado","Domingo")) -> Sexta-feira
A31: =IF(Parametros!$B$14+20<=EOMONTH(Parametros!$B$14,0),Parametros!$B$14+20,"") -> 46347 | B31: =IF(A31="","",CHOOSE(WEEKDAY(A31,2),"Segunda-feira","Terça-feira","Quarta-feira","Quinta-feira","Sexta-feira","Sábado","Domingo")) -> Sábado
A32: =IF(Parametros!$B$14+21<=EOMONTH(Parametros!$B$14,0),Parametros!$B$14+21,"") -> 46348 | B32: =IF(A32="","",CHOOSE(WEEKDAY(A32,2),"Segunda-feira","Terça-feira","Quarta-feira","Quinta-feira","Sexta-feira","Sábado","Domingo")) -> Domingo
A33: =IF(Parametros!$B$14+22<=EOMONTH(Parametros!$B$14,0),Parametros!$B$14+22,"") -> 46349 | B33: =IF(A33="","",CHOOSE(WEEKDAY(A33,2),"Segunda-feira","Terça-feira","Quarta-feira","Quinta-feira","Sexta-feira","Sábado","Domingo")) -> Segunda-feira
A34: =IF(Parametros!$B$14+23<=EOMONTH(Parametros!$B$14,0),Parametros!$B$14+23,"") -> 46350 | B34: =IF(A34="","",CHOOSE(WEEKDAY(A34,2),"Segunda-feira","Terça-feira","Quarta-feira","Quinta-feira","Sexta-feira","Sábado","Domingo")) -> Terça-feira
A35: =IF(Parametros!$B$14+24<=EOMONTH(Parametros!$B$14,0),Parametros!$B$14+24,"") -> 46351 | B35: =IF(A35="","",CHOOSE(WEEKDAY(A35,2),"Segunda-feira","Terça-feira","Quarta-feira","Quinta-feira","Sexta-feira","Sábado","Domingo")) -> Quarta-feira
A36: =IF(Parametros!$B$14+25<=EOMONTH(Parametros!$B$14,0),Parametros!$B$14+25,"") -> 46352 | B36: =IF(A36="","",CHOOSE(WEEKDAY(A36,2),"Segunda-feira","Terça-feira","Quarta-feira","Quinta-feira","Sexta-feira","Sábado","Domingo")) -> Quinta-feira
A37: =IF(Parametros!$B$14+26<=EOMONTH(Parametros!$B$14,0),Parametros!$B$14+26,"") -> 46353 | B37: =IF(A37="","",CHOOSE(WEEKDAY(A37,2),"Segunda-feira","Terça-feira","Quarta-feira","Quinta-feira","Sexta-feira","Sábado","Domingo")) -> Sexta-feira
A38: =IF(Parametros!$B$14+27<=EOMONTH(Parametros!$B$14,0),Parametros!$B$14+27,"") -> 46354 | B38: =IF(A38="","",CHOOSE(WEEKDAY(A38,2),"Segunda-feira","Terça-feira","Quarta-feira","Quinta-feira","Sexta-feira","Sábado","Domingo")) -> Sábado
A39: =IF(Parametros!$B$14+28<=EOMONTH(Parametros!$B$14,0),Parametros!$B$14+28,"") -> 46355 | B39: =IF(A39="","",CHOOSE(WEEKDAY(A39,2),"Segunda-feira","Terça-feira","Quarta-feira","Quinta-feira","Sexta-feira","Sábado","Domingo")) -> Domingo
A40: =IF(Parametros!$B$14+29<=EOMONTH(Parametros!$B$14,0),Parametros!$B$14+29,"") -> 46356 | B40: =IF(A40="","",CHOOSE(WEEKDAY(A40,2),"Segunda-feira","Terça-feira","Quarta-feira","Quinta-feira","Sexta-feira","Sábado","Domingo")) -> Segunda-feira
A41: =IF(Parametros!$B$14+30<=EOMONTH(Parametros!$B$14,0),Parametros!$B$14+30,"") | B41: =IF(A41="","",CHOOSE(WEEKDAY(A41,2),"Segunda-feira","Terça-feira","Quarta-feira","Quinta-feira","Sexta-feira","Sábado","Domingo"))
...

Sheet 2_Analise
A1: 2 – ANÁLISE: HORÁRIO A CUMPRIR × PONTO BATIDO (HORAS EXTRAS, DESCONTOS E COMPENSAÇÃO)
A2: ="Empregado(a): "&Parametros!B7&" | Mês: "&Parametros!B15&"/"&Parametros!B16&" | Limite de extra por dia: "&TEXT(Parametros!B19,"h:mm")&"h" -> Empregado(a): | Mês: NOVEMBRO/2026 | Limite de extra por dia: 2:00h
A3: Células amarelas = informe só se precisar (exceções). Células brancas = fórmulas (não digite). A linha 7 explica como cada coluna é calculada.
A5: DIA | C5: INFORMAÇÕES DO DIA (preencha só o que for exceção) | G5: HORÁRIO A CUMPRIR (para análise) | L5: PONTO BATIDO (vem da aba 1) | Q5: ANÁLISE DO DIA: HORAS EXTRAS E DESCONTOS | U5: COMPENSAÇÃO (limite de hora extra por dia) | Y5: RESULTADO PARA A FOLHA AJUSTADA
A6: DATA | B6: DIA DA SEMANA | C6: SITUAÇÃO (só se for diferente) | D6: LIBERAÇÃO ANTECIPADA ÀS | E6: SAÍDA REAL INFORMADA | F6: SITUAÇÃO CONSIDERADA | G6: ENTRADA PREVISTA | H6: PARADA PREVISTA | I6: RETORNO PREVISTO | J6: SAÍDA PREVISTA | K6: HORAS EXIGIDAS | L6: ENTRADA REAL | M6: INTERVALO REAL | N6: SAÍDA REAL CONSIDERADA | O6: HORAS TRABALHADAS | P6: ALERTA | Q6: HORA EXTRA REAL | R6: DESCONTO PROVÁVEL | S6: EXTRA LANÇADA NO DIA | T6: EXCEDENTE A COMPENSAR | U6: RECEBE COMPENSAÇÃO? | V6: ESPAÇO LIVRE NO DIA | W6: SALDO A COMPENSAR ANTES DO DIA | X6: COMPENSAÇÃO LANÇADA NO DIA | Y6: EXTRAS NA FOLHA AJUSTADA | Z6: SALDO A COMPENSAR APÓS O DIA
C7: Informe: TRABALHO, PREVISTO, FOLGA, FERIADO ou FALTA. Em branco = automático. | D7: Hora em que a diretoria liberou o setor mais cedo. | E7: Só se a pessoa ficou além do que está no papel (ex.: ficou até 17:00). | F7: C, ou automático: tem ponto = TRABALHO; feriado; fim de semana = FOLGA; senão PREVISTO. | G7: Da tabela de horários (Parâmetros). | H7: Da tabela de horários. | I7: Da tabela de horários. | J7: Tabela de horários ou a liberação antecipada (D). | K7: (Saída − Entrada) − intervalo. Sem intervalo se a saída é antes do almoço. | L7: Entrada batida (aba 1). | M7: Retorno − Parada batidos; sem eles, usa o intervalo previsto se saiu depois do almoço. | N7: Saída real informada (E) ou a maior entre Saída e Extras-Saída do papel. | O7: (Saída real − Entrada real) − intervalo real. Dia PREVISTO = horas exigidas. | P7: Avisa ponto incompleto. | Q7: Trabalhadas − exigidas, se positivo. | R7: Exigidas − trabalhadas, se positivo (ou falta). | S7: Menor entre a hora extra real e o limite/dia (zero em liberação antecipada, conforme Parâmetros). | T7: Hora extra real − extra lançada no dia. | U7: SIM: dia de trabalho sem liberação antecipada, sem desconto e sem alerta. | V7: Limite/dia − extra já lançada no dia (só se recebe). | W7: Soma dos excedentes dos dias anteriores − compensações já lançadas. | X7: Menor entre o espaço livre e o saldo a compensar. | Y7: Extra lançada no dia + compensação lançada. | Z7: Saldo antes + excedente do dia − compensação do dia.
A8: =1_Ponto_Batido!A11 -> 46327 | B8: =IF(A8="","",CHOOSE(WEEKDAY(A8,2),"Segunda-feira","Terça-feira","Quarta-feira","Quinta-feira","Sexta-feira","Sábado","Domingo")) -> Domingo | F8: =IF(A8="","",IF(C8<>"",C8,IF(1_Ponto_Batido!C11<>"","TRABALHO",IF(COUNTIF(Parametros!$A$35:$A$50,A8)>0,"FERIADO",IF(WEEKDAY(A8,2)>=6,"FOLGA","PREVISTO"))))) -> FOLGA | G8: =IF(OR(F8="TRABALHO",F8="PREVISTO",F8="FALTA"),IF(INDEX(Parametros!$B$25:$B$31,WEEKDAY(A8,2))<>"",INDEX(Parametros!$B$25:$B$31,WEEKDAY(A8,2)),""),"") | H8: =IF(G8="","",INDEX(Parametros!$C$25:$C$31,WEEKDAY(A8,2))) | I8: =IF(G8="","",INDEX(Parametros!$D$25:$D$31,WEEKDAY(A8,2))) | J8: =IF(G8="","",IF(D8<>"",D8,INDEX(Parametros!$E$25:$E$31,WEEKDAY(A8,2)))) | K8: =IF(G8="",0,ROUND(IF(J8<=H8,J8-G8,(J8-G8)-(I8-H8))*1440,0)/1440) -> 0 | L8: =IF(F8<>"TRABALHO","",IF(1_Ponto_Batido!C11="","",1_Ponto_Batido!C11)) | M8: =IF(L8="","",IF(AND(1_Ponto_Batido!D11<>"",1_Ponto_Batido!E11<>""),1_Ponto_Batido!E11-1_Ponto_Batido!D11,IF(N8>=I8,I8-H8,0))) | N8: =IF(L8="","",IF(E8<>"",E8,MAX(1_Ponto_Batido!F11,1_Ponto_Batido!H11))) | O8: =IF(F8="TRABALHO",IF(OR(L8="",N8=0),0,ROUND(MAX(0,(N8-L8)-M8)*1440,0)/1440),IF(F8="PREVISTO",K8,0)) -> 0 | P8: =IF(F8="TRABALHO",IF(OR(L8="",N8=0),"Ponto incompleto: falta entrada ou saída",IF(N8<=L8,"Saída antes da entrada","")),"") | Q8: =IF(OR(F8<>"TRABALHO",P8<>""),0,ROUND(MAX(0,O8-K8)*1440,0)/1440) -> 0 | R8: =IF(F8="FALTA",K8,IF(AND(F8="TRABALHO",P8=""),ROUND(MAX(0,K8-O8)*1440,0)/1440,0)) -> 0 | S8: =IF(Q8=0,0,IF(AND(D8<>"",Parametros!$B$20="NÃO"),0,MIN(Q8,Parametros!$B$19))) -> 0 | T8: =ROUND((Q8-S8)*1440,0)/1440 -> 0 | U8: =IF(AND(OR(F8="TRABALHO",F8="PREVISTO"),D8="",R8=0,P8=""),"SIM","NÃO") -> NÃO | V8: =IF(U8="SIM",MAX(0,Parametros!$B$19-S8),0) -> 0 | W8: =ROUND((SUM(T$7:T7)-SUM(X$7:X7))*1440,0)/1440 -> 0 | X8: =IF(U8="SIM",MIN(V8,W8),0) -> 0 | Y8: =S8+X8 -> 0 | Z8: =ROUND((W8+T8-X8)*1440,0)/1440 -> 0
A9: =1_Ponto_Batido!A12 -> 46328 | B9: =IF(A9="","",CHOOSE(WEEKDAY(A9,2),"Segunda-feira","Terça-feira","Quarta-feira","Quinta-feira","Sexta-feira","Sábado","Domingo")) -> Segunda-feira | F9: =IF(A9="","",IF(C9<>"",C9,IF(1_Ponto_Batido!C12<>"","TRABALHO",IF(COUNTIF(Parametros!$A$35:$A$50,A9)>0,"FERIADO",IF(WEEKDAY(A9,2)>=6,"FOLGA","PREVISTO"))))) -> FERIADO | G9: =IF(OR(F9="TRABALHO",F9="PREVISTO",F9="FALTA"),IF(INDEX(Parametros!$B$25:$B$31,WEEKDAY(A9,2))<>"",INDEX(Parametros!$B$25:$B$31,WEEKDAY(A9,2)),""),"") | H9: =IF(G9="","",INDEX(Parametros!$C$25:$C$31,WEEKDAY(A9,2))) | I9: =IF(G9="","",INDEX(Parametros!$D$25:$D$31,WEEKDAY(A9,2))) | J9: =IF(G9="","",IF(D9<>"",D9,INDEX(Parametros!$E$25:$E$31,WEEKDAY(A9,2)))) | K9: =IF(G9="",0,ROUND(IF(J9<=H9,J9-G9,(J9-G9)-(I9-H9))*1440,0)/1440) -> 0 | L9: =IF(F9<>"TRABALHO","",IF(1_Ponto_Batido!C12="","",1_Ponto_Batido!C12)) | M9: =IF(L9="","",IF(AND(1_Ponto_Batido!D12<>"",1_Ponto_Batido!E12<>""),1_Ponto_Batido!E12-1_Ponto_Batido!D12,IF(N9>=I9,I9-H9,0))) | N9: =IF(L9="","",IF(E9<>"",E9,MAX(1_Ponto_Batido!F12,1_Ponto_Batido!H12))) | O9: =IF(F9="TRABALHO",IF(OR(L9="",N9=0),0,ROUND(MAX(0,(N9-L9)-M9)*1440,0)/1440),IF(F9="PREVISTO",K9,0)) -> 0 | P9: =IF(F9="TRABALHO",IF(OR(L9="",N9=0),"Ponto incompleto: falta entrada ou saída",IF(N9<=L9,"Saída antes da entrada","")),"") | Q9: =IF(OR(F9<>"TRABALHO",P9<>""),0,ROUND(MAX(0,O9-K9)*1440,0)/1440) -> 0 | R9: =IF(F9="FALTA",K9,IF(AND(F9="TRABALHO",P9=""),ROUND(MAX(0,K9-O9)*1440,0)/1440,0)) -> 0 | S9: =IF(Q9=0,0,IF(AND(D9<>"",Parametros!$B$20="NÃO"),0,MIN(Q9,Parametros!$B$19))) -> 0 | T9: =ROUND((Q9-S9)*1440,0)/1440 -> 0 | U9: =IF(AND(OR(F9="TRABALHO",F9="PREVISTO"),D9="",R9=0,P9=""),"SIM","NÃO") -> NÃO | V9: =IF(U9="SIM",MAX(0,Parametros!$B$19-S9),0) -> 0 | W9: =ROUND((SUM(T$7:T8)-SUM(X$7:X8))*1440,0)/1440 -> 0 | X9: =IF(U9="SIM",MIN(V9,W9),0) -> 0 | Y9: =S9+X9 -> 0 | Z9: =ROUND((W9+T9-X9)*1440,0)/1440 -> 0
A10: =1_Ponto_Batido!A13 -> 46329 | B10: =IF(A10="","",CHOOSE(WEEKDAY(A10,2),"Segunda-feira","Terça-feira","Quarta-feira","Quinta-feira","Sexta-feira","Sábado","Domingo")) -> Terça-feira | F10: =IF(A10="","",IF(C10<>"",C10,IF(1_Ponto_Batido!C13<>"","TRABALHO",IF(COUNTIF(Parametros!$A$35:$A$50,A10)>0,"FERIADO",IF(WEEKDAY(A10,2)>=6,"FOLGA","PREVISTO"))))) -> PREVISTO | G10: =IF(OR(F10="TRABALHO",F10="PREVISTO",F10="FALTA"),IF(INDEX(Parametros!$B$25:$B$31,WEEKDAY(A10,2))<>"",INDEX(Parametros!$B$25:$B$31,WEEKDAY(A10,2)),""),"") -> 0.33333333 | H10: =IF(G10="","",INDEX(Parametros!$C$25:$C$31,WEEKDAY(A10,2))) -> 0.5 | I10: =IF(G10="","",INDEX(Parametros!$D$25:$D$31,WEEKDAY(A10,2))) -> 0.54166667 | J10: =IF(G10="","",IF(D10<>"",D10,INDEX(Parametros!$E$25:$E$31,WEEKDAY(A10,2)))) -> 0.70833333 | K10: =IF(G10="",0,ROUND(IF(J10<=H10,J10-G10,(J10-G10)-(I10-H10))*1440,0)/1440) -> 0.33333333 | L10: =IF(F10<>"TRABALHO","",IF(1_Ponto_Batido!C13="","",1_Ponto_Batido!C13)) | M10: =IF(L10="","",IF(AND(1_Ponto_Batido!D13<>"",1_Ponto_Batido!E13<>""),1_Ponto_Batido!E13-1_Ponto_Batido!D13,IF(N10>=I10,I10-H10,0))) | N10: =IF(L10="","",IF(E10<>"",E10,MAX(1_Ponto_Batido!F13,1_Ponto_Batido!H13))) | O10: =IF(F10="TRABALHO",IF(OR(L10="",N10=0),0,ROUND(MAX(0,(N10-L10)-M10)*1440,0)/1440),IF(F10="PREVISTO",K10,0)) -> 0.33333333 | P10: =IF(F10="TRABALHO",IF(OR(L10="",N10=0),"Ponto incompleto: falta entrada ou saída",IF(N10<=L10,"Saída antes da entrada","")),"") | Q10: =IF(OR(F10<>"TRABALHO",P10<>""),0,ROUND(MAX(0,O10-K10)*1440,0)/1440) -> 0 | R10: =IF(F10="FALTA",K10,IF(AND(F10="TRABALHO",P10=""),ROUND(MAX(0,K10-O10)*1440,0)/1440,0)) -> 0 | S10: =IF(Q10=0,0,IF(AND(D10<>"",Parametros!$B$20="NÃO"),0,MIN(Q10,Parametros!$B$19))) -> 0 | T10: =ROUND((Q10-S10)*1440,0)/1440 -> 0 | U10: =IF(AND(OR(F10="TRABALHO",F10="PREVISTO"),D10="",R10=0,P10=""),"SIM","NÃO") -> SIM | V10: =IF(U10="SIM",MAX(0,Parametros!$B$19-S10),0) -> 0.083333333 | W10: =ROUND((SUM(T$7:T9)-SUM(X$7:X9))*1440,0)/1440 -> 0 | X10: =IF(U10="SIM",MIN(V10,W10),0) -> 0 | Y10: =S10+X10 -> 0 | Z10: =ROUND((W10+T10-X10)*1440,0)/1440 -> 0
A11: =1_Ponto_Batido!A14 -> 46330 | B11: =IF(A11="","",CHOOSE(WEEKDAY(A11,2),"Segunda-feira","Terça-feira","Quarta-feira","Quinta-feira","Sexta-feira","Sábado","Domingo")) -> Quarta-feira | F11: =IF(A11="","",IF(C11<>"",C11,IF(1_Ponto_Batido!C14<>"","TRABALHO",IF(COUNTIF(Parametros!$A$35:$A$50,A11)>0,"FERIADO",IF(WEEKDAY(A11,2)>=6,"FOLGA","PREVISTO"))))) -> PREVISTO | G11: =IF(OR(F11="TRABALHO",F11="PREVISTO",F11="FALTA"),IF(INDEX(Parametros!$B$25:$B$31,WEEKDAY(A11,2))<>"",INDEX(Parametros!$B$25:$B$31,WEEKDAY(A11,2)),""),"") -> 0.33333333 | H11: =IF(G11="","",INDEX(Parametros!$C$25:$C$31,WEEKDAY(A11,2))) -> 0.5 | I11: =IF(G11="","",INDEX(Parametros!$D$25:$D$31,WEEKDAY(A11,2))) -> 0.54166667 | J11: =IF(G11="","",IF(D11<>"",D11,INDEX(Parametros!$E$25:$E$31,WEEKDAY(A11,2)))) -> 0.70833333 | K11: =IF(G11="",0,ROUND(IF(J11<=H11,J11-G11,(J11-G11)-(I11-H11))*1440,0)/1440) -> 0.33333333 | L11: =IF(F11<>"TRABALHO","",IF(1_Ponto_Batido!C14="","",1_Ponto_Batido!C14)) | M11: =IF(L11="","",IF(AND(1_Ponto_Batido!D14<>"",1_Ponto_Batido!E14<>""),1_Ponto_Batido!E14-1_Ponto_Batido!D14,IF(N11>=I11,I11-H11,0))) | N11: =IF(L11="","",IF(E11<>"",E11,MAX(1_Ponto_Batido!F14,1_Ponto_Batido!H14))) | O11: =IF(F11="TRABALHO",IF(OR(L11="",N11=0),0,ROUND(MAX(0,(N11-L11)-M11)*1440,0)/1440),IF(F11="PREVISTO",K11,0)) -> 0.33333333 | P11: =IF(F11="TRABALHO",IF(OR(L11="",N11=0),"Ponto incompleto: falta entrada ou saída",IF(N11<=L11,"Saída antes da entrada","")),"") | Q11: =IF(OR(F11<>"TRABALHO",P11<>""),0,ROUND(MAX(0,O11-K11)*1440,0)/1440) -> 0 | R11: =IF(F11="FALTA",K11,IF(AND(F11="TRABALHO",P11=""),ROUND(MAX(0,K11-O11)*1440,0)/1440,0)) -> 0 | S11: =IF(Q11=0,0,IF(AND(D11<>"",Parametros!$B$20="NÃO"),0,MIN(Q11,Parametros!$B$19))) -> 0 | T11: =ROUND((Q11-S11)*1440,0)/1440 -> 0 | U11: =IF(AND(OR(F11="TRABALHO",F11="PREVISTO"),D11="",R11=0,P11=""),"SIM","NÃO") -> SIM | V11: =IF(U11="SIM",MAX(0,Parametros!$B$19-S11),0) -> 0.083333333 | W11: =ROUND((SUM(T$7:T10)-SUM(X$7:X10))*1440,0)/1440 -> 0 | X11: =IF(U11="SIM",MIN(V11,W11),0) -> 0 | Y11: =S11+X11 -> 0 | Z11: =ROUND((W11+T11-X11)*1440,0)/1440 -> 0
A12: =1_Ponto_Batido!A15 -> 46331 | B12: =IF(A12="","",CHOOSE(WEEKDAY(A12,2),"Segunda-feira","Terça-feira","Quarta-feira","Quinta-feira","Sexta-feira","Sábado","Domingo")) -> Quinta-feira | F12: =IF(A12="","",IF(C12<>"",C12,IF(1_Ponto_Batido!C15<>"","TRABALHO",IF(COUNTIF(Parametros!$A$35:$A$50,A12)>0,"FERIADO",IF(WEEKDAY(A12,2)>=6,"FOLGA","PREVISTO"))))) -> PREVISTO | G12: =IF(OR(F12="TRABALHO",F12="PREVISTO",F12="FALTA"),IF(INDEX(Parametros!$B$25:$B$31,WEEKDAY(A12,2))<>"",INDEX(Parametros!$B$25:$B$31,WEEKDAY(A12,2)),""),"") -> 0.33333333 | H12: =IF(G12="","",INDEX(Parametros!$C$25:$C$31,WEEKDAY(A12,2))) -> 0.5 | I12: =IF(G12="","",INDEX(Parametros!$D$25:$D$31,WEEKDAY(A12,2))) -> 0.54166667 | J12: =IF(G12="","",IF(D12<>"",D12,INDEX(Parametros!$E$25:$E$31,WEEKDAY(A12,2)))) -> 0.70833333 | K12: =IF(G12="",0,ROUND(IF(J12<=H12,J12-G12,(J12-G12)-(I12-H12))*1440,0)/1440) -> 0.33333333 | L12: =IF(F12<>"TRABALHO","",IF(1_Ponto_Batido!C15="","",1_Ponto_Batido!C15)) | M12: =IF(L12="","",IF(AND(1_Ponto_Batido!D15<>"",1_Ponto_Batido!E15<>""),1_Ponto_Batido!E15-1_Ponto_Batido!D15,IF(N12>=I12,I12-H12,0))) | N12: =IF(L12="","",IF(E12<>"",E12,MAX(1_Ponto_Batido!F15,1_Ponto_Batido!H15))) | O12: =IF(F12="TRABALHO",IF(OR(L12="",N12=0),0,ROUND(MAX(0,(N12-L12)-M12)*1440,0)/1440),IF(F12="PREVISTO",K12,0)) -> 0.33333333 | P12: =IF(F12="TRABALHO",IF(OR(L12="",N12=0),"Ponto incompleto: falta entrada ou saída",IF(N12<=L12,"Saída antes da entrada","")),"") | Q12: =IF(OR(F12<>"TRABALHO",P12<>""),0,ROUND(MAX(0,O12-K12)*1440,0)/1440) -> 0 | R12: =IF(F12="FALTA",K12,IF(AND(F12="TRABALHO",P12=""),ROUND(MAX(0,K12-O12)*1440,0)/1440,0)) -> 0 | S12: =IF(Q12=0,0,IF(AND(D12<>"",Parametros!$B$20="NÃO"),0,MIN(Q12,Parametros!$B$19))) -> 0 | T12: =ROUND((Q12-S12)*1440,0)/1440 -> 0 | U12: =IF(AND(OR(F12="TRABALHO",F12="PREVISTO"),D12="",R12=0,P12=""),"SIM","NÃO") -> SIM | V12: =IF(U12="SIM",MAX(0,Parametros!$B$19-S12),0) -> 0.083333333 | W12: =ROUND((SUM(T$7:T11)-SUM(X$7:X11))*1440,0)/1440 -> 0 | X12: =IF(U12="SIM",MIN(V12,W12),0) -> 0 | Y12: =S12+X12 -> 0 | Z12: =ROUND((W12+T12-X12)*1440,0)/1440 -> 0
A13: =1_Ponto_Batido!A16 -> 46332 | B13: =IF(A13="","",CHOOSE(WEEKDAY(A13,2),"Segunda-feira","Terça-feira","Quarta-feira","Quinta-feira","Sexta-feira","Sábado","Domingo")) -> Sexta-feira | F13: =IF(A13="","",IF(C13<>"",C13,IF(1_Ponto_Batido!C16<>"","TRABALHO",IF(COUNTIF(Parametros!$A$35:$A$50,A13)>0,"FERIADO",IF(WEEKDAY(A13,2)>=6,"FOLGA","PREVISTO"))))) -> PREVISTO | G13: =IF(OR(F13="TRABALHO",F13="PREVISTO",F13="FALTA"),IF(INDEX(Parametros!$B$25:$B$31,WEEKDAY(A13,2))<>"",INDEX(Parametros!$B$25:$B$31,WEEKDAY(A13,2)),""),"") -> 0.33333333 | H13: =IF(G13="","",INDEX(Parametros!$C$25:$C$31,WEEKDAY(A13,2))) -> 0.5 | I13: =IF(G13="","",INDEX(Parametros!$D$25:$D$31,WEEKDAY(A13,2))) -> 0.54166667 | J13: =IF(G13="","",IF(D13<>"",D13,INDEX(Parametros!$E$25:$E$31,WEEKDAY(A13,2)))) -> 0.70833333 | K13: =IF(G13="",0,ROUND(IF(J13<=H13,J13-G13,(J13-G13)-(I13-H13))*1440,0)/1440) -> 0.33333333 | L13: =IF(F13<>"TRABALHO","",IF(1_Ponto_Batido!C16="","",1_Ponto_Batido!C16)) | M13: =IF(L13="","",IF(AND(1_Ponto_Batido!D16<>"",1_Ponto_Batido!E16<>""),1_Ponto_Batido!E16-1_Ponto_Batido!D16,IF(N13>=I13,I13-H13,0))) | N13: =IF(L13="","",IF(E13<>"",E13,MAX(1_Ponto_Batido!F16,1_Ponto_Batido!H16))) | O13: =IF(F13="TRABALHO",IF(OR(L13="",N13=0),0,ROUND(MAX(0,(N13-L13)-M13)*1440,0)/1440),IF(F13="PREVISTO",K13,0)) -> 0.33333333 | P13: =IF(F13="TRABALHO",IF(OR(L13="",N13=0),"Ponto incompleto: falta entrada ou saída",IF(N13<=L13,"Saída antes da entrada","")),"") | Q13: =IF(OR(F13<>"TRABALHO",P13<>""),0,ROUND(MAX(0,O13-K13)*1440,0)/1440) -> 0 | R13: =IF(F13="FALTA",K13,IF(AND(F13="TRABALHO",P13=""),ROUND(MAX(0,K13-O13)*1440,0)/1440,0)) -> 0 | S13: =IF(Q13=0,0,IF(AND(D13<>"",Parametros!$B$20="NÃO"),0,MIN(Q13,Parametros!$B$19))) -> 0 | T13: =ROUND((Q13-S13)*1440,0)/1440 -> 0 | U13: =IF(AND(OR(F13="TRABALHO",F13="PREVISTO"),D13="",R13=0,P13=""),"SIM","NÃO") -> SIM | V13: =IF(U13="SIM",MAX(0,Parametros!$B$19-S13),0) -> 0.083333333 | W13: =ROUND((SUM(T$7:T12)-SUM(X$7:X12))*1440,0)/1440 -> 0 | X13: =IF(U13="SIM",MIN(V13,W13),0) -> 0 | Y13: =S13+X13 -> 0 | Z13: =ROUND((W13+T13-X13)*1440,0)/1440 -> 0
A14: =1_Ponto_Batido!A17 -> 46333 | B14: =IF(A14="","",CHOOSE(WEEKDAY(A14,2),"Segunda-feira","Terça-feira","Quarta-feira","Quinta-feira","Sexta-feira","Sábado","Domingo")) -> Sábado | F14: =IF(A14="","",IF(C14<>"",C14,IF(1_Ponto_Batido!C17<>"","TRABALHO",IF(COUNTIF(Parametros!$A$35:$A$50,A14)>0,"FERIADO",IF(WEEKDAY(A14,2)>=6,"FOLGA","PREVISTO"))))) -> FOLGA | G14: =IF(OR(F14="TRABALHO",F14="PREVISTO",F14="FALTA"),IF(INDEX(Parametros!$B$25:$B$31,WEEKDAY(A14,2))<>"",INDEX(Parametros!$B$25:$B$31,WEEKDAY(A14,2)),""),"") | H14: =IF(G14="","",INDEX(Parametros!$C$25:$C$31,WEEKDAY(A14,2))) | I14: =IF(G14="","",INDEX(Parametros!$D$25:$D$31,WEEKDAY(A14,2))) | J14: =IF(G14="","",IF(D14<>"",D14,INDEX(Parametros!$E$25:$E$31,WEEKDAY(A14,2)))) | K14: =IF(G14="",0,ROUND(IF(J14<=H14,J14-G14,(J14-G14)-(I14-H14))*1440,0)/1440) -> 0 | L14: =IF(F14<>"TRABALHO","",IF(1_Ponto_Batido!C17="","",1_Ponto_Batido!C17)) | M14: =IF(L14="","",IF(AND(1_Ponto_Batido!D17<>"",1_Ponto_Batido!E17<>""),1_Ponto_Batido!E17-1_Ponto_Batido!D17,IF(N14>=I14,I14-H14,0))) | N14: =IF(L14="","",IF(E14<>"",E14,MAX(1_Ponto_Batido!F17,1_Ponto_Batido!H17))) | O14: =IF(F14="TRABALHO",IF(OR(L14="",N14=0),0,ROUND(MAX(0,(N14-L14)-M14)*1440,0)/1440),IF(F14="PREVISTO",K14,0)) -> 0 | P14: =IF(F14="TRABALHO",IF(OR(L14="",N14=0),"Ponto incompleto: falta entrada ou saída",IF(N14<=L14,"Saída antes da entrada","")),"") | Q14: =IF(OR(F14<>"TRABALHO",P14<>""),0,ROUND(MAX(0,O14-K14)*1440,0)/1440) -> 0 | R14: =IF(F14="FALTA",K14,IF(AND(F14="TRABALHO",P14=""),ROUND(MAX(0,K14-O14)*1440,0)/1440,0)) -> 0 | S14: =IF(Q14=0,0,IF(AND(D14<>"",Parametros!$B$20="NÃO"),0,MIN(Q14,Parametros!$B$19))) -> 0 | T14: =ROUND((Q14-S14)*1440,0)/1440 -> 0 | U14: =IF(AND(OR(F14="TRABALHO",F14="PREVISTO"),D14="",R14=0,P14=""),"SIM","NÃO") -> NÃO | V14: =IF(U14="SIM",MAX(0,Parametros!$B$19-S14),0) -> 0 | W14: =ROUND((SUM(T$7:T13)-SUM(X$7:X13))*1440,0)/1440 -> 0 | X14: =IF(U14="SIM",MIN(V14,W14),0) -> 0 | Y14: =S14+X14 -> 0 | Z14: =ROUND((W14+T14-X14)*1440,0)/1440 -> 0
A15: =1_Ponto_Batido!A18 -> 46334 | B15: =IF(A15="","",CHOOSE(WEEKDAY(A15,2),"Segunda-feira","Terça-feira","Quarta-feira","Quinta-feira","Sexta-feira","Sábado","Domingo")) -> Domingo | F15: =IF(A15="","",IF(C15<>"",C15,IF(1_Ponto_Batido!C18<>"","TRABALHO",IF(COUNTIF(Parametros!$A$35:$A$50,A15)>0,"FERIADO",IF(WEEKDAY(A15,2)>=6,"FOLGA","PREVISTO"))))) -> FOLGA | G15: =IF(OR(F15="TRABALHO",F15="PREVISTO",F15="FALTA"),IF(INDEX(Parametros!$B$25:$B$31,WEEKDAY(A15,2))<>"",INDEX(Parametros!$B$25:$B$31,WEEKDAY(A15,2)),""),"") | H15: =IF(G15="","",INDEX(Parametros!$C$25:$C$31,WEEKDAY(A15,2))) | I15: =IF(G15="","",INDEX(Parametros!$D$25:$D$31,WEEKDAY(A15,2))) | J15: =IF(G15="","",IF(D15<>"",D15,INDEX(Parametros!$E$25:$E$31,WEEKDAY(A15,2)))) | K15: =IF(G15="",0,ROUND(IF(J15<=H15,J15-G15,(J15-G15)-(I15-H15))*1440,0)/1440) -> 0 | L15: =IF(F15<>"TRABALHO","",IF(1_Ponto_Batido!C18="","",1_Ponto_Batido!C18)) | M15: =IF(L15="","",IF(AND(1_Ponto_Batido!D18<>"",1_Ponto_Batido!E18<>""),1_Ponto_Batido!E18-1_Ponto_Batido!D18,IF(N15>=I15,I15-H15,0))) | N15: =IF(L15="","",IF(E15<>"",E15,MAX(1_Ponto_Batido!F18,1_Ponto_Batido!H18))) | O15: =IF(F15="TRABALHO",IF(OR(L15="",N15=0),0,ROUND(MAX(0,(N15-L15)-M15)*1440,0)/1440),IF(F15="PREVISTO",K15,0)) -> 0 | P15: =IF(F15="TRABALHO",IF(OR(L15="",N15=0),"Ponto incompleto: falta entrada ou saída",IF(N15<=L15,"Saída antes da entrada","")),"") | Q15: =IF(OR(F15<>"TRABALHO",P15<>""),0,ROUND(MAX(0,O15-K15)*1440,0)/1440) -> 0 | R15: =IF(F15="FALTA",K15,IF(AND(F15="TRABALHO",P15=""),ROUND(MAX(0,K15-O15)*1440,0)/1440,0)) -> 0 | S15: =IF(Q15=0,0,IF(AND(D15<>"",Parametros!$B$20="NÃO"),0,MIN(Q15,Parametros!$B$19))) -> 0 | T15: =ROUND((Q15-S15)*1440,0)/1440 -> 0 | U15: =IF(AND(OR(F15="TRABALHO",F15="PREVISTO"),D15="",R15=0,P15=""),"SIM","NÃO") -> NÃO | V15: =IF(U15="SIM",MAX(0,Parametros!$B$19-S15),0) -> 0 | W15: =ROUND((SUM(T$7:T14)-SUM(X$7:X14))*1440,0)/1440 -> 0 | X15: =IF(U15="SIM",MIN(V15,W15),0) -> 0 | Y15: =S15+X15 -> 0 | Z15: =ROUND((W15+T15-X15)*1440,0)/1440 -> 0
A16: =1_Ponto_Batido!A19 -> 46335 | B16: =IF(A16="","",CHOOSE(WEEKDAY(A16,2),"Segunda-feira","Terça-feira","Quarta-feira","Quinta-feira","Sexta-feira","Sábado","Domingo")) -> Segunda-feira | F16: =IF(A16="","",IF(C16<>"",C16,IF(1_Ponto_Batido!C19<>"","TRABALHO",IF(COUNTIF(Parametros!$A$35:$A$50,A16)>0,"FERIADO",IF(WEEKDAY(A16,2)>=6,"FOLGA","PREVISTO"))))) -> PREVISTO | G16: =IF(OR(F16="TRABALHO",F16="PREVISTO",F16="FALTA"),IF(INDEX(Parametros!$B$25:$B$31,WEEKDAY(A16,2))<>"",INDEX(Parametros!$B$25:$B$31,WEEKDAY(A16,2)),""),"") -> 0.33333333 | H16: =IF(G16="","",INDEX(Parametros!$C$25:$C$31,WEEKDAY(A16,2))) -> 0.5 | I16: =IF(G16="","",INDEX(Parametros!$D$25:$D$31,WEEKDAY(A16,2))) -> 0.54166667 | J16: =IF(G16="","",IF(D16<>"",D16,INDEX(Parametros!$E$25:$E$31,WEEKDAY(A16,2)))) -> 0.70833333 | K16: =IF(G16="",0,ROUND(IF(J16<=H16,J16-G16,(J16-G16)-(I16-H16))*1440,0)/1440) -> 0.33333333 | L16: =IF(F16<>"TRABALHO","",IF(1_Ponto_Batido!C19="","",1_Ponto_Batido!C19)) | M16: =IF(L16="","",IF(AND(1_Ponto_Batido!D19<>"",1_Ponto_Batido!E19<>""),1_Ponto_Batido!E19-1_Ponto_Batido!D19,IF(N16>=I16,I16-H16,0))) | N16: =IF(L16="","",IF(E16<>"",E16,MAX(1_Ponto_Batido!F19,1_Ponto_Batido!H19))) | O16: =IF(F16="TRABALHO",IF(OR(L16="",N16=0),0,ROUND(MAX(0,(N16-L16)-M16)*1440,0)/1440),IF(F16="PREVISTO",K16,0)) -> 0.33333333 | P16: =IF(F16="TRABALHO",IF(OR(L16="",N16=0),"Ponto incompleto: falta entrada ou saída",IF(N16<=L16,"Saída antes da entrada","")),"") | Q16: =IF(OR(F16<>"TRABALHO",P16<>""),0,ROUND(MAX(0,O16-K16)*1440,0)/1440) -> 0 | R16: =IF(F16="FALTA",K16,IF(AND(F16="TRABALHO",P16=""),ROUND(MAX(0,K16-O16)*1440,0)/1440,0)) -> 0 | S16: =IF(Q16=0,0,IF(AND(D16<>"",Parametros!$B$20="NÃO"),0,MIN(Q16,Parametros!$B$19))) -> 0 | T16: =ROUND((Q16-S16)*1440,0)/1440 -> 0 | U16: =IF(AND(OR(F16="TRABALHO",F16="PREVISTO"),D16="",R16=0,P16=""),"SIM","NÃO") -> SIM | V16: =IF(U16="SIM",MAX(0,Parametros!$B$19-S16),0) -> 0.083333333 | W16: =ROUND((SUM(T$7:T15)-SUM(X$7:X15))*1440,0)/1440 -> 0 | X16: =IF(U16="SIM",MIN(V16,W16),0) -> 0 | Y16: =S16+X16 -> 0 | Z16: =ROUND((W16+T16-X16)*1440,0)/1440 -> 0
A17: =1_Ponto_Batido!A20 -> 46336 | B17: =IF(A17="","",CHOOSE(WEEKDAY(A17,2),"Segunda-feira","Terça-feira","Quarta-feira","Quinta-feira","Sexta-feira","Sábado","Domingo")) -> Terça-feira | F17: =IF(A17="","",IF(C17<>"",C17,IF(1_Ponto_Batido!C20<>"","TRABALHO",IF(COUNTIF(Parametros!$A$35:$A$50,A17)>0,"FERIADO",IF(WEEKDAY(A17,2)>=6,"FOLGA","PREVISTO"))))) -> PREVISTO | G17: =IF(OR(F17="TRABALHO",F17="PREVISTO",F17="FALTA"),IF(INDEX(Parametros!$B$25:$B$31,WEEKDAY(A17,2))<>"",INDEX(Parametros!$B$25:$B$31,WEEKDAY(A17,2)),""),"") -> 0.33333333 | H17: =IF(G17="","",INDEX(Parametros!$C$25:$C$31,WEEKDAY(A17,2))) -> 0.5 | I17: =IF(G17="","",INDEX(Parametros!$D$25:$D$31,WEEKDAY(A17,2))) -> 0.54166667 | J17: =IF(G17="","",IF(D17<>"",D17,INDEX(Parametros!$E$25:$E$31,WEEKDAY(A17,2)))) -> 0.70833333 | K17: =IF(G17="",0,ROUND(IF(J17<=H17,J17-G17,(J17-G17)-(I17-H17))*1440,0)/1440) -> 0.33333333 | L17: =IF(F17<>"TRABALHO","",IF(1_Ponto_Batido!C20="","",1_Ponto_Batido!C20)) | M17: =IF(L17="","",IF(AND(1_Ponto_Batido!D20<>"",1_Ponto_Batido!E20<>""),1_Ponto_Batido!E20-1_Ponto_Batido!D20,IF(N17>=I17,I17-H17,0))) | N17: =IF(L17="","",IF(E17<>"",E17,MAX(1_Ponto_Batido!F20,1_Ponto_Batido!H20))) | O17: =IF(F17="TRABALHO",IF(OR(L17="",N17=0),0,ROUND(MAX(0,(N17-L17)-M17)*1440,0)/1440),IF(F17="PREVISTO",K17,0)) -> 0.33333333 | P17: =IF(F17="TRABALHO",IF(OR(L17="",N17=0),"Ponto incompleto: falta entrada ou saída",IF(N17<=L17,"Saída antes da entrada","")),"") | Q17: =IF(OR(F17<>"TRABALHO",P17<>""),0,ROUND(MAX(0,O17-K17)*1440,0)/1440) -> 0 | R17: =IF(F17="FALTA",K17,IF(AND(F17="TRABALHO",P17=""),ROUND(MAX(0,K17-O17)*1440,0)/1440,0)) -> 0 | S17: =IF(Q17=0,0,IF(AND(D17<>"",Parametros!$B$20="NÃO"),0,MIN(Q17,Parametros!$B$19))) -> 0 | T17: =ROUND((Q17-S17)*1440,0)/1440 -> 0 | U17: =IF(AND(OR(F17="TRABALHO",F17="PREVISTO"),D17="",R17=0,P17=""),"SIM","NÃO") -> SIM | V17: =IF(U17="SIM",MAX(0,Parametros!$B$19-S17),0) -> 0.083333333 | W17: =ROUND((SUM(T$7:T16)-SUM(X$7:X16))*1440,0)/1440 -> 0 | X17: =IF(U17="SIM",MIN(V17,W17),0) -> 0 | Y17: =S17+X17 -> 0 | Z17: =ROUND((W17+T17-X17)*1440,0)/1440 -> 0
A18: =1_Ponto_Batido!A21 -> 46337 | B18: =IF(A18="","",CHOOSE(WEEKDAY(A18,2),"Segunda-feira","Terça-feira","Quarta-feira","Quinta-feira","Sexta-feira","Sábado","Domingo")) -> Quarta-feira | F18: =IF(A18="","",IF(C18<>"",C18,IF(1_Ponto_Batido!C21<>"","TRABALHO",IF(COUNTIF(Parametros!$A$35:$A$50,A18)>0,"FERIADO",IF(WEEKDAY(A18,2)>=6,"FOLGA","PREVISTO"))))) -> PREVISTO | G18: =IF(OR(F18="TRABALHO",F18="PREVISTO",F18="FALTA"),IF(INDEX(Parametros!$B$25:$B$31,WEEKDAY(A18,2))<>"",INDEX(Parametros!$B$25:$B$31,WEEKDAY(A18,2)),""),"") -> 0.33333333 | H18: =IF(G18="","",INDEX(Parametros!$C$25:$C$31,WEEKDAY(A18,2))) -> 0.5 | I18: =IF(G18="","",INDEX(Parametros!$D$25:$D$31,WEEKDAY(A18,2))) -> 0.54166667 | J18: =IF(G18="","",IF(D18<>"",D18,INDEX(Parametros!$E$25:$E$31,WEEKDAY(A18,2)))) -> 0.70833333 | K18: =IF(G18="",0,ROUND(IF(J18<=H18,J18-G18,(J18-G18)-(I18-H18))*1440,0)/1440) -> 0.33333333 | L18: =IF(F18<>"TRABALHO","",IF(1_Ponto_Batido!C21="","",1_Ponto_Batido!C21)) | M18: =IF(L18="","",IF(AND(1_Ponto_Batido!D21<>"",1_Ponto_Batido!E21<>""),1_Ponto_Batido!E21-1_Ponto_Batido!D21,IF(N18>=I18,I18-H18,0))) | N18: =IF(L18="","",IF(E18<>"",E18,MAX(1_Ponto_Batido!F21,1_Ponto_Batido!H21))) | O18: =IF(F18="TRABALHO",IF(OR(L18="",N18=0),0,ROUND(MAX(0,(N18-L18)-M18)*1440,0)/1440),IF(F18="PREVISTO",K18,0)) -> 0.33333333 | P18: =IF(F18="TRABALHO",IF(OR(L18="",N18=0),"Ponto incompleto: falta entrada ou saída",IF(N18<=L18,"Saída antes da entrada","")),"") | Q18: =IF(OR(F18<>"TRABALHO",P18<>""),0,ROUND(MAX(0,O18-K18)*1440,0)/1440) -> 0 | R18: =IF(F18="FALTA",K18,IF(AND(F18="TRABALHO",P18=""),ROUND(MAX(0,K18-O18)*1440,0)/1440,0)) -> 0 | S18: =IF(Q18=0,0,IF(AND(D18<>"",Parametros!$B$20="NÃO"),0,MIN(Q18,Parametros!$B$19))) -> 0 | T18: =ROUND((Q18-S18)*1440,0)/1440 -> 0 | U18: =IF(AND(OR(F18="TRABALHO",F18="PREVISTO"),D18="",R18=0,P18=""),"SIM","NÃO") -> SIM | V18: =IF(U18="SIM",MAX(0,Parametros!$B$19-S18),0) -> 0.083333333 | W18: =ROUND((SUM(T$7:T17)-SUM(X$7:X17))*1440,0)/1440 -> 0 | X18: =IF(U18="SIM",MIN(V18,W18),0) -> 0 | Y18: =S18+X18 -> 0 | Z18: =ROUND((W18+T18-X18)*1440,0)/1440 -> 0
A19: =1_Ponto_Batido!A22 -> 46338 | B19: =IF(A19="","",CHOOSE(WEEKDAY(A19,2),"Segunda-feira","Terça-feira","Quarta-feira","Quinta-feira","Sexta-feira","Sábado","Domingo")) -> Quinta-feira | F19: =IF(A19="","",IF(C19<>"",C19,IF(1_Ponto_Batido!C22<>"","TRABALHO",IF(COUNTIF(Parametros!$A$35:$A$50,A19)>0,"FERIADO",IF(WEEKDAY(A19,2)>=6,"FOLGA","PREVISTO"))))) -> PREVISTO | G19: =IF(OR(F19="TRABALHO",F19="PREVISTO",F19="FALTA"),IF(INDEX(Parametros!$B$25:$B$31,WEEKDAY(A19,2))<>"",INDEX(Parametros!$B$25:$B$31,WEEKDAY(A19,2)),""),"") -> 0.33333333 | H19: =IF(G19="","",INDEX(Parametros!$C$25:$C$31,WEEKDAY(A19,2))) -> 0.5 | I19: =IF(G19="","",INDEX(Parametros!$D$25:$D$31,WEEKDAY(A19,2))) -> 0.54166667 | J19: =IF(G19="","",IF(D19<>"",D19,INDEX(Parametros!$E$25:$E$31,WEEKDAY(A19,2)))) -> 0.70833333 | K19: =IF(G19="",0,ROUND(IF(J19<=H19,J19-G19,(J19-G19)-(I19-H19))*1440,0)/1440) -> 0.33333333 | L19: =IF(F19<>"TRABALHO","",IF(1_Ponto_Batido!C22="","",1_Ponto_Batido!C22)) | M19: =IF(L19="","",IF(AND(1_Ponto_Batido!D22<>"",1_Ponto_Batido!E22<>""),1_Ponto_Batido!E22-1_Ponto_Batido!D22,IF(N19>=I19,I19-H19,0))) | N19: =IF(L19="","",IF(E19<>"",E19,MAX(1_Ponto_Batido!F22,1_Ponto_Batido!H22))) | O19: =IF(F19="TRABALHO",IF(OR(L19="",N19=0),0,ROUND(MAX(0,(N19-L19)-M19)*1440,0)/1440),IF(F19="PREVISTO",K19,0)) -> 0.33333333 | P19: =IF(F19="TRABALHO",IF(OR(L19="",N19=0),"Ponto incompleto: falta entrada ou saída",IF(N19<=L19,"Saída antes da entrada","")),"") | Q19: =IF(OR(F19<>"TRABALHO",P19<>""),0,ROUND(MAX(0,O19-K19)*1440,0)/1440) -> 0 | R19: =IF(F19="FALTA",K19,IF(AND(F19="TRABALHO",P19=""),ROUND(MAX(0,K19-O19)*1440,0)/1440,0)) -> 0 | S19: =IF(Q19=0,0,IF(AND(D19<>"",Parametros!$B$20="NÃO"),0,MIN(Q19,Parametros!$B$19))) -> 0 | T19: =ROUND((Q19-S19)*1440,0)/1440 -> 0 | U19: =IF(AND(OR(F19="TRABALHO",F19="PREVISTO"),D19="",R19=0,P19=""),"SIM","NÃO") -> SIM | V19: =IF(U19="SIM",MAX(0,Parametros!$B$19-S19),0) -> 0.083333333 | W19: =ROUND((SUM(T$7:T18)-SUM(X$7:X18))*1440,0)/1440 -> 0 | X19: =IF(U19="SIM",MIN(V19,W19),0) -> 0 | Y19: =S19+X19 -> 0 | Z19: =ROUND((W19+T19-X19)*1440,0)/1440 -> 0
... A38: =1_Ponto_Batido!A41 | B38: =IF(A38="","",CHOOSE(WEEKDAY(A38,2),"Segunda-feira","Terça-feira","Quarta-feira","Quinta-feira","Sexta-feira","Sábado","Domingo")) | F38: =IF(A38="","",IF(C38<>"",C38,IF(1_Ponto_Batido!C41<>"","TRABALHO",IF(COUNTIF(Parametros!$A$35:$A$50,A38)>0,"FERIADO",IF(WEEKDAY(A38,2)>=6,"FOLGA","PREVISTO"))))) | G38: =IF(OR(F38="TRABALHO",F38="PREVISTO",F38="FALTA"),IF(INDEX(Parametros!$B$25:$B$31,WEEKDAY(A38,2))<>"",INDEX(Parametros!$B$25:$B$31,WEEKDAY(A38,2)),""),"") | H38: =IF(G38="","",INDEX(Parametros!$C$25:$C$31,WEEKDAY(A38,2))) | I38: =IF(G38="","",INDEX(Parametros!$D$25:$D$31,WEEKDAY(A38,2))) | J38: =IF(G38="","",IF(D38<>"",D38,INDEX(Parametros!$E$25:$E$31,WEEKDAY(A38,2)))) | K38: =IF(G38="",0,ROUND(IF(J38<=H38,J38-G38,(J38-G38)-(I38-H38))*1440,0)/1440) -> 0 | L38: =IF(F38<>"TRABALHO","",IF(1_Ponto_Batido!C41="","",1_Ponto_Batido!C41)) | M38: =IF(L38="","",IF(AND(1_Ponto_Batido!D41<>"",1_Ponto_Batido!E41<>""),1_Ponto_Batido!E41-1_Ponto_Batido!D41,IF(N38>=I38,I38-H38,0))) | N38: =IF(L38="","",IF(E38<>"",E38,MAX(1_Ponto_Batido!F41,1_Ponto_Batido!H41))) | O38: =IF(F38="TRABALHO",IF(OR(L38="",N38=0),0,ROUND(MAX(0,(N38-L38)-M38)*1440,0)/1440),IF(F38="PREVISTO",K38,0)) -> 0 | P38: =IF(F38="TRABALHO",IF(OR(L38="",N38=0),"Ponto incompleto: falta entrada ou saída",IF(N38<=L38,"Saída antes da entrada","")),"") | Q38: =IF(OR(F38<>"TRABALHO",P38<>""),0,ROUND(MAX(0,O38-K38)*1440,0)/1440) -> 0 | R38: =IF(F38="FALTA",K38,IF(AND(F38="TRABALHO",P38=""),ROUND(MAX(0,K38-O38)*1440,0)/1440,0)) -> 0 | S38: =IF(Q38=0,0,IF(AND(D38<>"",Parametros!$B$20="NÃO"),0,MIN(Q38,Parametros!$B$19))) -> 0 | T38: =ROUND((Q38-S38)*1440,0)/1440 -> 0 | U38: =IF(AND(OR(F38="TRABALHO",F38="PREVISTO"),D38="",R38=0,P38=""),"SIM","NÃO") -> NÃO | V38: =IF(U38="SIM",MAX(0,Parametros!$B$19-S38),0) -> 0 | W38: =ROUND((SUM(T$7:T37)-SUM(X$7:X37))*1440,0)/1440 -> 0 | X38: =IF(U38="SIM",MIN(V38,W38),0) -> 0 | Y38: =S38+X38 -> 0 | Z38: =ROUND((W38+T38-X38)*1440,0)/1440 -> 0
A39: TOTAIS | K39: =SUM(K8:K38) -> 6.3333333 | O39: =SUM(O8:O38) -> 6.3333333 | Q39: =SUM(Q8:Q38) -> 0 | R39: =SUM(R8:R38) -> 0 | S39: =SUM(S8:S38) -> 0 | T39: =SUM(T8:T38) -> 0 | X39: =SUM(X8:X38) -> 0 | Y39: =SUM(Y8:Y38) -> 0
A41: RESUMO E CONFERÊNCIA
A42: Horas extras reais (acima do horário a cumprir) | G42: =Q39 -> 0
A43: lançadas no próprio dia (até o limite diário) | G43: =S39 -> 0
A44: excedente que precisa ser compensado em outros dias | G44: =T39 -> 0
A45: Compensação lançada em outros dias (folha ajustada) | G45: =X39 -> 0
A46: Saldo ainda NÃO compensado (passa para o mês seguinte) | G46: =ROUND((T39-X39)*1440,0)/1440 -> 0
A47: Total de horas extras na folha ajustada | G47: =Y39 -> 0
A48: Descontos prováveis (horas a menos / faltas) | G48: =R39 -> 0
A49: Saldo líquido do mês (extras reais − descontos) | G49: =IF(Q39>=R39,"+"&TEXT(Q39-R39,"[h]:mm"),"-"&TEXT(R39-Q39,"[h]:mm")) -> +0:00
A50: CONFERÊNCIA: extras reais = lançadas + saldo ainda não compensado | G50: =IF(ROUND((Q39-Y39-(T39-X39))*1440,0)=0,"OK","DIVERGENTE – revise") -> OK
A51: CONFERÊNCIA: nenhum dia acima do limite diário | G51: =IF(SUMPRODUCT((Y8:Y38>Parametros!B19+0.000001)*1)=0,"OK","DIVERGENTE – revise") -> OK
A52: Dias com ponto incompleto (alerta) | G52: =COUNTIF(P8:P38,"?*") -> 0

Sheet 3_Ponto_Ajustado
A1: ="3 – FOLHA DE PONTO AJUSTADA: HORAS EXTRAS LIMITADAS A "&TEXT(Parametros!B19,"h:mm")&"H POR DIA E COMPENSAÇÃO" -> 3 – FOLHA DE PONTO AJUSTADA: HORAS EXTRAS LIMITADAS A 2:00H POR DIA E COMPENSAÇÃO
A2: Gerada automaticamente a partir das abas 1 e 2. Linhas de COMPENSAÇÃO = horas extras excedentes de outros dias, lançadas aqui para respeitar o limite diário. Guarde a folha original (aba 1).
A3: =" EMPREGADOR: "&Parametros!B4 -> EMPREGADOR: | I3: ="CEI / CNPJ Nº: "&Parametros!B5 -> CEI / CNPJ Nº:
A4: =" ENDEREÇO: "&Parametros!B6 -> ENDEREÇO: | I4: ="DATA DE ADMISSÃO: "&IF(Parametros!B10="","",TEXT(Parametros!B10,"dd/mm/yyyy")) -> DATA DE ADMISSÃO:
A5: =" EMPREGADO(A): "&Parametros!B7 -> EMPREGADO(A): | I5: ="CTPS Nº E SÉRIE: "&Parametros!B9 -> CTPS Nº E SÉRIE:
A6: =" FUNÇÃO: "&Parametros!B8 -> FUNÇÃO: | I6: ="HORÁRIO SEG. A SEXTA: "&Parametros!B11 -> HORÁRIO SEG. A SEXTA:
A7: =" HORÁRIO AOS SÁBADOS: "&Parametros!B12 -> HORÁRIO AOS SÁBADOS: | E7: ="DESCANSO SEMANAL: "&Parametros!B13 -> DESCANSO SEMANAL: | I7: ="MÊS: "&Parametros!B15&" ANO: "&Parametros!B16 -> MÊS: NOVEMBRO ANO: 2026
A9: DIA | B9: DIA DA SEMANA | C9: ENTRADA | D9: INTERVALO | F9: SAÍDA | G9: EXTRAS | I9: HORAS TRABALHADAS | J9: HORAS EXTRAS | K9: TIPO DO DIA | L9: VISTO DO RESP. HORA EXTRA | M9: ASSINATURA DO FUNCIONÁRIO | N9: EXPLICAÇÃO DO AJUSTE DA FOLHA DE PONTO POR CONTA DE HORA EXTRA E COMPENSAÇÃO
D10: PARADA | E10: RETORNO | G10: ENTRADA | H10: SAÍDA
A11: =2_Analise!A8 -> 46327 | B11: =2_Analise!B8 -> Domingo | C11: =IF(OR(2_Analise!F8="TRABALHO",2_Analise!F8="PREVISTO"),IF(2_Analise!R8>0,2_Analise!L8,2_Analise!G8),"") | D11: =IF(C11="","",IF(F11>2_Analise!H8,2_Analise!H8,"")) | E11: =IF(D11="","",2_Analise!I8) | F11: =IF(C11="","",IF(2_Analise!R8>0,2_Analise!N8,2_Analise!J8)) | G11: =IF(N(2_Analise!Y8)>0,2_Analise!J8,"") | H11: =IF(G11="","",ROUND((2_Analise!J8+2_Analise!Y8)*1440,0)/1440) | I11: =IF(C11="","",ROUND((IF(H11<>"",H11,F11)-C11-IF(D11<>"",E11-D11,0))*1440,0)/1440) | J11: =IF(N(2_Analise!Y8)>0,2_Analise!Y8,"") | K11: =IF(2_Analise!F8="","",IF(2_Analise!F8="FOLGA","FOLGA",IF(2_Analise!F8="FERIADO","FERIADO",IF(2_Analise!F8="FALTA","FALTA",IF(2_Analise!X8>0,IF(2_Analise!S8>0,"EXTRA + COMPENSAÇÃO","COMPENSAÇÃO"),IF(2_Analise!S8>0,"EXTRA",IF(2_Analise!T8>0,"EXTRA A COMPENSAR",IF(2_Analise!R8>0,"DESCONTO PROVÁVEL",IF(2_Analise!F8="PREVISTO","PREVISTO","NORMAL"))))))))) -> FOLGA | N11: =IF(2_Analise!F8="","",IF(2_Analise!F8="FOLGA","FOLGA",IF(2_Analise!F8="FERIADO","FERIADO"&IFERROR(" – "&INDEX(Parametros!$B$35:$B$50,MATCH(A11,Parametros!$A$35:$A$50,0)),""),IF(2_Analise!F8="FALTA","FALTA: desconto de "&IF(MINUTE(2_Analise!R8)=0,HOUR(2_Analise!R8)&"h",HOUR(2_Analise!R8)&"h"&TEXT(MINUTE(2_Analise!R8),"00"))&" (horário exigido não cumprido).",IF(2_Analise!P8<>"","CONFERIR: "&2_Analise!P8&". Complete a aba 1.",IF(2_Analise!R8>0,"DESCONTO PROVÁVEL de "&IF(MINUTE(2_Analise!R8)=0,HOUR(2_Analise!R8)&"h",HOUR(2_Analise!R8)&"h"&TEXT(MINUTE(2_Analise!R8),"00"))&": exigido "&IF(MINUTE(2_Analise!K8)=0,HOUR(2_Analise!K8)&"h",HOUR(2_Analise!K8)&"h"&TEXT(MINUTE(2_Analise!K8),"00"))&", cumprido "&IF(MINUTE(2_Analise!O8)=0,HOUR(2_Analise!O8)&"h",HOUR(2_Analise!O8)&"h"&TEXT(MINUTE(2_Analise!O8),"00"))&".",IF(2_Analise!X8>0,IF(2_Analise!S8>0,"EXTRA "&IF(MINUTE(2_Analise!S8)=0,HOUR(2_Analise!S8)&"h",HOUR(2_Analise!S8)&"h"&TEXT(MINUTE(2_Analise!S8),"00"))&" e COMPENSAÇÃO DE "&IF(MINUTE(2_Analise!X8)=0,HOUR(2_Analise!X8)&"h",HOUR(2_Analise!X8)&"h"&TEXT(MINUTE(2_Analise!X8),"00"))&" (horas excedentes de outros dias).","COMPENSAÇÃO DE "&IF(MINUTE(2_Analise!X8)=0,HOUR(2_Analise!X8)&"h",HOUR(2_Analise!X8)&"h"&TEXT(MINUTE(2_Analise!X8),"00"))&": horas extras excedentes de outros dias, lançadas neste dia para respeitar o limite diário."),IF(AND(2_Analise!S8>0,2_Analise!T8>0),TEXT(A11,"dd/mm")&": extras de "&IF(MINUTE(2_Analise!Q8)=0,HOUR(2_Analise!Q8)&"h",HOUR(2_Analise!Q8)&"h"&TEXT(MINUTE(2_Analise!Q8),"00"))&". Lançadas "&IF(MINUTE(2_Analise!S8)=0,HOUR(2_Analise!S8)&"h",HOUR(2_Analise!S8)&"h"&TEXT(MINUTE(2_Analise!S8),"00"))&" no dia (limite de "&IF(MINUTE(Parametros!$B$19)=0,HOUR(Parametros!$B$19)&"h",HOUR(Parametros!$B$19)&"h"&TEXT(MINUTE(Parametros!$B$19),"00"))&") e "&IF(MINUTE(2_Analise!T8)=0,HOUR(2_Analise!T8)&"h",HOUR(2_Analise!T8)&"h"&TEXT(MINUTE(2_Analise!T8),"00"))&" a compensar em outros dias.",IF(2_Analise!T8>0,TEXT(A11,"dd/mm")&": funcionária permaneceu em atividade até "&IF(MINUTE(2_Analise!N8)=0,HOUR(2_Analise!N8)&"h",HOUR(2_Analise!N8)&"h"&TEXT(MINUTE(2_Analise!N8),"00"))&" por necessidade do serviço"&IF(2_Analise!D8<>"",". Diretoria liberou os demais colaboradores às "&IF(MINUTE(2_Analise!D8)=0,HOUR(2_Analise!D8)&"h",HOUR(2_Analise!D8)&"h"&TEXT(MINUTE(2_Analise!D8),"00")),"")&". Extras: "&IF(MINUTE(2_Analise!T8)=0,HOUR(2_Analise!T8)&"h",HOUR(2_Analise!T8)&"h"&TEXT(MINUTE(2_Analise!T8),"00"))&" redistribuídas para compensação em outros dias.",IF(2_Analise!S8>0,"EXTRA "&IF(MINUTE(2_Analise!S8)=0,HOUR(2_Analise!S8)&"h",HOUR(2_Analise!S8)&"h"&TEXT(MINUTE(2_Analise!S8),"00")),IF(2_Analise!F8="PREVISTO","Dia previsto: expediente normal, sem extras.","NORMAL: horário cumprido."))))))))))) -> FOLGA
A12: =2_Analise!A9 -> 46328 | B12: =2_Analise!B9 -> Segunda-feira | C12: =IF(OR(2_Analise!F9="TRABALHO",2_Analise!F9="PREVISTO"),IF(2_Analise!R9>0,2_Analise!L9,2_Analise!G9),"") | D12: =IF(C12="","",IF(F12>2_Analise!H9,2_Analise!H9,"")) | E12: =IF(D12="","",2_Analise!I9) | F12: =IF(C12="","",IF(2_Analise!R9>0,2_Analise!N9,2_Analise!J9)) | G12: =IF(N(2_Analise!Y9)>0,2_Analise!J9,"") | H12: =IF(G12="","",ROUND((2_Analise!J9+2_Analise!Y9)*1440,0)/1440) | I12: =IF(C12="","",ROUND((IF(H12<>"",H12,F12)-C12-IF(D12<>"",E12-D12,0))*1440,0)/1440) | J12: =IF(N(2_Analise!Y9)>0,2_Analise!Y9,"") | K12: =IF(2_Analise!F9="","",IF(2_Analise!F9="FOLGA","FOLGA",IF(2_Analise!F9="FERIADO","FERIADO",IF(2_Analise!F9="FALTA","FALTA",IF(2_Analise!X9>0,IF(2_Analise!S9>0,"EXTRA + COMPENSAÇÃO","COMPENSAÇÃO"),IF(2_Analise!S9>0,"EXTRA",IF(2_Analise!T9>0,"EXTRA A COMPENSAR",IF(2_Analise!R9>0,"DESCONTO PROVÁVEL",IF(2_Analise!F9="PREVISTO","PREVISTO","NORMAL"))))))))) -> FERIADO | N12: =IF(2_Analise!F9="","",IF(2_Analise!F9="FOLGA","FOLGA",IF(2_Analise!F9="FERIADO","FERIADO"&IFERROR(" – "&INDEX(Parametros!$B$35:$B$50,MATCH(A12,Parametros!$A$35:$A$50,0)),""),IF(2_Analise!F9="FALTA","FALTA: desconto de "&IF(MINUTE(2_Analise!R9)=0,HOUR(2_Analise!R9)&"h",HOUR(2_Analise!R9)&"h"&TEXT(MINUTE(2_Analise!R9),"00"))&" (horário exigido não cumprido).",IF(2_Analise!P9<>"","CONFERIR: "&2_Analise!P9&". Complete a aba 1.",IF(2_Analise!R9>0,"DESCONTO PROVÁVEL de "&IF(MINUTE(2_Analise!R9)=0,HOUR(2_Analise!R9)&"h",HOUR(2_Analise!R9)&"h"&TEXT(MINUTE(2_Analise!R9),"00"))&": exigido "&IF(MINUTE(2_Analise!K9)=0,HOUR(2_Analise!K9)&"h",HOUR(2_Analise!K9)&"h"&TEXT(MINUTE(2_Analise!K9),"00"))&", cumprido "&IF(MINUTE(2_Analise!O9)=0,HOUR(2_Analise!O9)&"h",HOUR(2_Analise!O9)&"h"&TEXT(MINUTE(2_Analise!O9),"00"))&".",IF(2_Analise!X9>0,IF(2_Analise!S9>0,"EXTRA "&IF(MINUTE(2_Analise!S9)=0,HOUR(2_Analise!S9)&"h",HOUR(2_Analise!S9)&"h"&TEXT(MINUTE(2_Analise!S9),"00"))&" e COMPENSAÇÃO DE "&IF(MINUTE(2_Analise!X9)=0,HOUR(2_Analise!X9)&"h",HOUR(2_Analise!X9)&"h"&TEXT(MINUTE(2_Analise!X9),"00"))&" (horas excedentes de outros dias).","COMPENSAÇÃO DE "&IF(MINUTE(2_Analise!X9)=0,HOUR(2_Analise!X9)&"h",HOUR(2_Analise!X9)&"h"&TEXT(MINUTE(2_Analise!X9),"00"))&": horas extras excedentes de outros dias, lançadas neste dia para respeitar o limite diário."),IF(AND(2_Analise!S9>0,2_Analise!T9>0),TEXT(A12,"dd/mm")&": extras de "&IF(MINUTE(2_Analise!Q9)=0,HOUR(2_Analise!Q9)&"h",HOUR(2_Analise!Q9)&"h"&TEXT(MINUTE(2_Analise!Q9),"00"))&". Lançadas "&IF(MINUTE(2_Analise!S9)=0,HOUR(2_Analise!S9)&"h",HOUR(2_Analise!S9)&"h"&TEXT(MINUTE(2_Analise!S9),"00"))&" no dia (limite de "&IF(MINUTE(Parametros!$B$19)=0,HOUR(Parametros!$B$19)&"h",HOUR(Parametros!$B$19)&"h"&TEXT(MINUTE(Parametros!$B$19),"00"))&") e "&IF(MINUTE(2_Analise!T9)=0,HOUR(2_Analise!T9)&"h",HOUR(2_Analise!T9)&"h"&TEXT(MINUTE(2_Analise!T9),"00"))&" a compensar em outros dias.",IF(2_Analise!T9>0,TEXT(A12,"dd/mm")&": funcionária permaneceu em atividade até "&IF(MINUTE(2_Analise!N9)=0,HOUR(2_Analise!N9)&"h",HOUR(2_Analise!N9)&"h"&TEXT(MINUTE(2_Analise!N9),"00"))&" por necessidade do serviço"&IF(2_Analise!D9<>"",". Diretoria liberou os demais colaboradores às "&IF(MINUTE(2_Analise!D9)=0,HOUR(2_Analise!D9)&"h",HOUR(2_Analise!D9)&"h"&TEXT(MINUTE(2_Analise!D9),"00")),"")&". Extras: "&IF(MINUTE(2_Analise!T9)=0,HOUR(2_Analise!T9)&"h",HOUR(2_Analise!T9)&"h"&TEXT(MINUTE(2_Analise!T9),"00"))&" redistribuídas para compensação em outros dias.",IF(2_Analise!S9>0,"EXTRA "&IF(MINUTE(2_Analise!S9)=0,HOUR(2_Analise!S9)&"h",HOUR(2_Analise!S9)&"h"&TEXT(MINUTE(2_Analise!S9),"00")),IF(2_Analise!F9="PREVISTO","Dia previsto: expediente normal, sem extras.","NORMAL: horário cumprido."))))))))))) -> FERIADO – Finados
A13: =2_Analise!A10 -> 46329 | B13: =2_Analise!B10 -> Terça-feira | C13: =IF(OR(2_Analise!F10="TRABALHO",2_Analise!F10="PREVISTO"),IF(2_Analise!R10>0,2_Analise!L10,2_Analise!G10),"") -> 0.33333333 | D13: =IF(C13="","",IF(F13>2_Analise!H10,2_Analise!H10,"")) -> 0.5 | E13: =IF(D13="","",2_Analise!I10) -> 0.54166667 | F13: =IF(C13="","",IF(2_Analise!R10>0,2_Analise!N10,2_Analise!J10)) -> 0.70833333 | G13: =IF(N(2_Analise!Y10)>0,2_Analise!J10,"") | H13: =IF(G13="","",ROUND((2_Analise!J10+2_Analise!Y10)*1440,0)/1440) | I13: =IF(C13="","",ROUND((IF(H13<>"",H13,F13)-C13-IF(D13<>"",E13-D13,0))*1440,0)/1440) -> 0.33333333 | J13: =IF(N(2_Analise!Y10)>0,2_Analise!Y10,"") | K13: =IF(2_Analise!F10="","",IF(2_Analise!F10="FOLGA","FOLGA",IF(2_Analise!F10="FERIADO","FERIADO",IF(2_Analise!F10="FALTA","FALTA",IF(2_Analise!X10>0,IF(2_Analise!S10>0,"EXTRA + COMPENSAÇÃO","COMPENSAÇÃO"),IF(2_Analise!S10>0,"EXTRA",IF(2_Analise!T10>0,"EXTRA A COMPENSAR",IF(2_Analise!R10>0,"DESCONTO PROVÁVEL",IF(2_Analise!F10="PREVISTO","PREVISTO","NORMAL"))))))))) -> PREVISTO | N13: =IF(2_Analise!F10="","",IF(2_Analise!F10="FOLGA","FOLGA",IF(2_Analise!F10="FERIADO","FERIADO"&IFERROR(" – "&INDEX(Parametros!$B$35:$B$50,MATCH(A13,Parametros!$A$35:$A$50,0)),""),IF(2_Analise!F10="FALTA","FALTA: desconto de "&IF(MINUTE(2_Analise!R10)=0,HOUR(2_Analise!R10)&"h",HOUR(2_Analise!R10)&"h"&TEXT(MINUTE(2_Analise!R10),"00"))&" (horário exigido não cumprido).",IF(2_Analise!P10<>"","CONFERIR: "&2_Analise!P10&". Complete a aba 1.",IF(2_Analise!R10>0,"DESCONTO PROVÁVEL de "&IF(MINUTE(2_Analise!R10)=0,HOUR(2_Analise!R10)&"h",HOUR(2_Analise!R10)&"h"&TEXT(MINUTE(2_Analise!R10),"00"))&": exigido "&IF(MINUTE(2_Analise!K10)=0,HOUR(2_Analise!K10)&"h",HOUR(2_Analise!K10)&"h"&TEXT(MINUTE(2_Analise!K10),"00"))&", cumprido "&IF(MINUTE(2_Analise!O10)=0,HOUR(2_Analise!O10)&"h",HOUR(2_Analise!O10)&"h"&TEXT(MINUTE(2_Analise!O10),"00"))&".",IF(2_Analise!X10>0,IF(2_Analise!S10>0,"EXTRA "&IF(MINUTE(2_Analise!S10)=0,HOUR(2_Analise!S10)&"h",HOUR(2_Analise!S10)&"h"&TEXT(MINUTE(2_Analise!S10),"00"))&" e COMPENSAÇÃO DE "&IF(MINUTE(2_Analise!X10)=0,HOUR(2_Analise!X10)&"h",HOUR(2_Analise!X10)&"h"&TEXT(MINUTE(2_Analise!X10),"00"))&" (horas excedentes de outros dias).","COMPENSAÇÃO DE "&IF(MINUTE(2_Analise!X10)=0,HOUR(2_Analise!X10)&"h",HOUR(2_Analise!X10)&"h"&TEXT(MINUTE(2_Analise!X10),"00"))&": horas extras excedentes de outros dias, lançadas neste dia para respeitar o limite diário."),IF(AND(2_Analise!S10>0,2_Analise!T10>0),TEXT(A13,"dd/mm")&": extras de "&IF(MINUTE(2_Analise!Q10)=0,HOUR(2_Analise!Q10)&"h",HOUR(2_Analise!Q10)&"h"&TEXT(MINUTE(2_Analise!Q10),"00"))&". Lançadas "&IF(MINUTE(2_Analise!S10)=0,HOUR(2_Analise!S10)&"h",HOUR(2_Analise!S10)&"h"&TEXT(MINUTE(2_Analise!S10),"00"))&" no dia (limite de "&IF(MINUTE(Parametros!$B$19)=0,HOUR(Parametros!$B$19)&"h",HOUR(Parametros!$B$19)&"h"&TEXT(MINUTE(Parametros!$B$19),"00"))&") e "&IF(MINUTE(2_Analise!T10)=0,HOUR(2_Analise!T10)&"h",HOUR(2_Analise!T10)&"h"&TEXT(MINUTE(2_Analise!T10),"00"))&" a compensar em outros dias.",IF(2_Analise!T10>0,TEXT(A13,"dd/mm")&": funcionária permaneceu em atividade até "&IF(MINUTE(2_Analise!N10)=0,HOUR(2_Analise!N10)&"h",HOUR(2_Analise!N10)&"h"&TEXT(MINUTE(2_Analise!N10),"00"))&" por necessidade do serviço"&IF(2_Analise!D10<>"",". Diretoria liberou os demais colaboradores às "&IF(MINUTE(2_Analise!D10)=0,HOUR(2_Analise!D10)&"h",HOUR(2_Analise!D10)&"h"&TEXT(MINUTE(2_Analise!D10),"00")),"")&". Extras: "&IF(MINUTE(2_Analise!T10)=0,HOUR(2_Analise!T10)&"h",HOUR(2_Analise!T10)&"h"&TEXT(MINUTE(2_Analise!T10),"00"))&" redistribuídas para compensação em outros dias.",IF(2_Analise!S10>0,"EXTRA "&IF(MINUTE(2_Analise!S10)=0,HOUR(2_Analise!S10)&"h",HOUR(2_Analise!S10)&"h"&TEXT(MINUTE(2_Analise!S10),"00")),IF(2_Analise!F10="PREVISTO","Dia previsto: expediente normal, sem extras.","NORMAL: horário cumprido."))))))))))) -> Dia previsto: expediente normal, sem extras.
